Workbook

Sheet Assumptions
A1: ATHENA - ROI ANALYSIS ASSUMPTIONS
A2: All blue values are adjustable inputs. Yellow cells require validation with customer.
A4: LABOR COST ASSUMPTIONS
A5: VA Hourly Rate (Philippines-based XP) | B5: 12 | C5: $/hour | D5: Fully loaded cost for Executive Partners
A6: Operations Staff Hourly Rate | B6: 25 | C6: $/hour | D6: US-based ops/IT staff for escalations
A7: Engineering/IT Hourly Rate | B7: 75 | C7: $/hour | D7: For incident response and remediation
A8: Working Hours per Month | B8: 160 | C8: hours | D8: Standard month
A10: TASK PROCESSING ASSUMPTIONS
A11: Minutes per Simple Task (data sync) | B11: 2 | C11: minutes | D11: Basic lookups, data transfers
A12: Minutes per Medium Task (multi-step) | B12: 8 | C12: minutes | D12: Conditional logic, multiple systems
A13: Minutes per Complex Task (ELA/DocuSign) | B13: 20 | C13: minutes | D13: Document processing, approvals
A14: Automation Efficiency Factor | B14: 0.85 | C14: ratio | D14: Not all tasks would be done manually - some would be skipped
A16: DISRUPTION COST ASSUMPTIONS
A17: Average Deal Value (ELA) | B17: 15000 | C17: $ | D17: Average contract value for Executive Leadership Agreements
A18: Deal Velocity Impact (days delayed) | B18: 3 | C18: days | D18: Avg delay when sales pipeline Zap goes down
A19: Deals in Pipeline at Any Time | B19: 50 | C19: deals | D19: Active deals that could be affected
A20: % Deals at Risk from Delay | B20: 0.05 | C20: ratio | D20: Conservative - deals lost due to delay
A21: Support Ticket Cost (per incident) | B21: 150 | C21: $ | D21: Internal cost to handle automation failure ticket
A22: Avg Tickets per Outage Day | B22: 25 | C22: tickets | D22: Based on VA volume and dependency
A23: Total Monthly Tasks (from Zap data) | B23: 303927 | C23: tasks | D23: Sum of top Zaps - update from Zap-Level ROI
A25: GOVERNANCE & SECURITY RISK ASSUMPTIONS
A26: Cost of Data Breach (avg) | B26: 150000 | C26: $ | D26: SMB data breach avg cost - conservative for their size
A27: Annual Probability of Breach (ungoverned) | B27: 0.08 | C27: ratio | D27: 8% annual probability without SSO/SCIM controls
A28: Annual Probability of Breach (governed) | B28: 0.02 | C28: ratio | D28: 2% with Enterprise controls
A29: Shadow IT Accounts | B29: 115 | C29: accounts | D29: Free accounts in past 90 days from dossier
A30: Compliance Audit Cost (per incident) | B30: 25000 | C30: $ | D30: External audit if governance gap discovered
A31: Annual Probability of Audit Issue | B31: 0.15 | C31: ratio | D31: Given current 40+ users on 25-seat cap
A34: CELL REFERENCE GUIDE (for other sheets)
A35: VA Hourly Rate | B35: B5
A36: Ops Staff Rate | B36: B6
A37: Engineering Rate | B37: B7
A38: Simple Task Minutes | B38: B10
A39: Medium Task Minutes | B39: B11
A40: Complex Task Minutes | B40: B12
A41: Efficiency Factor | B41: B13
A42: Avg Deal Value | B42: B16
A43: Deal Delay Days | B43: B17
A44: Deals in Pipeline | B44: B18
A45: % Deals at Risk | B45: B19
A46: Ticket Cost | B46: B20
...

Sheet Zap-Level ROI
A1: ZAP-LEVEL AUTOMATION VALUE
A2: Quantifies time savings value for each major Zap based on task volume and complexity
A4: Zap Name | B4: Use Case | C4: Owner | D4: Tasks/Month | E4: Complexity | F4: Min/Task | G4: Hours Saved/Mo | H4: Hourly Rate | I4: Monthly Value | J4: Annual Value | K4: Notes
A5: (LIVE) Catch Signed ELA - Part 3 | B5: Sales Pipeline | C5: julian.sanchez@athena.com | D5: 151244 | E5: Complex | F5: =Assumptions!$B$12 -> 8 | G5: =(D5*F5/60)*Assumptions!$B$13 -> 403317.33 | H5: =Assumptions!$B$5 -> 12 | I5: =G5*H5 -> 4839808 | J5: =I5*12 -> 58077696 | K5: 63% of all tasks - ELA processing
A6: (LIVE) Catch Zoom recordings → HubSpot | B6: Data Management | C6: julian.sanchez@athena.com | D6: 61322 | E6: Medium | F6: =Assumptions!$B$11 -> 2 | G6: =(D6*F6/60)*Assumptions!$B$13 -> 40881.333 | H6: =Assumptions!$B$5 -> 12 | I6: =G6*H6 -> 490576 | J6: =I6*12 -> 5886912 | K6: Customer intelligence capture
A7: (STG) Catch Zoom recordings → HubSpot | B7: Data Management | C7: julian.sanchez@athena.com | D7: 58408 | E7: Medium | F7: =Assumptions!$B$11 -> 2 | G7: =(D7*F7/60)*Assumptions!$B$13 -> 38938.667 | H7: =Assumptions!$B$5 -> 12 | I7: =G7*H7 -> 467264 | J7: =I7*12 -> 5607168 | K7: Staging environment
A8: Calendly <> HubSpot - 2WFC Details | B8: Lead Management | C8: den.planas@athena.com | D8: 14358 | E8: Simple | F8: =Assumptions!$B$10 -> 0 | G8: =(D8*F8/60)*Assumptions!$B$13 -> 0 | H8: =Assumptions!$B$5 -> 12 | I8: =G8*H8 -> 0 | J8: =I8*12 -> 0 | K8: Lead data sync
A9: Trial - Gender Zap V2 | B9: Lead Management | C9: den.planas@athena.com | D9: 5328 | E9: Simple | F9: =Assumptions!$B$10 -> 0 | G9: =(D9*F9/60)*Assumptions!$B$13 -> 0 | H9: =Assumptions!$B$5 -> 12 | I9: =G9*H9 -> 0 | J9: =I9*12 -> 0 | K9: Lead enrichment
A10: Meta CAPI - Demand | B10: Sales Pipeline | C10: adam.crabbe@athena.com | D10: 3592 | E10: Simple | F10: =Assumptions!$B$10 -> 0 | G10: =(D10*F10/60)*Assumptions!$B$13 -> 0 | H10: =Assumptions!$B$5 -> 12 | I10: =G10*H10 -> 0 | J10: =I10*12 -> 0 | K10: Ad attribution
A11: OpenAI Assistant - Prod | B11: Customer Support | C11: jimmy.giraldo@athena.com | D11: 3340 | E11: Complex | F11: =Assumptions!$B$12 -> 8 | G11: =(D11*F11/60)*Assumptions!$B$13 -> 8906.6667 | H11: =Assumptions!$B$5 -> 12 | I11: =G11*H11 -> 106880 | J11: =I11*12 -> 1282560 | K11: AI-powered support
A12: OpenAI Assistant - Result Receiver | B12: Customer Support | C12: jimmy.giraldo@athena.com | D12: 2512 | E12: Medium | F12: =Assumptions!$B$11 -> 2 | G12: =(D12*F12/60)*Assumptions!$B$13 -> 1674.6667 | H12: =Assumptions!$B$5 -> 12 | I12: =G12*H12 -> 20096 | J12: =I12*12 -> 241152 | K12: Support response handling
A13: Handle General DocuSign - Master | B13: Sales Pipeline | C13: cristhian@athena.com | D13: 1998 | E13: Complex | F13: =Assumptions!$B$12 -> 8 | G13: =(D13*F13/60)*Assumptions!$B$13 -> 5328 | H13: =Assumptions!$B$5 -> 12 | I13: =G13*H13 -> 63936 | J13: =I13*12 -> 767232 | K13: Contract automation
A14: Scheduling Zap | B14: Operations | C14: stella.maingi@athena.com | D14: 1825 | E14: Simple | F14: =Assumptions!$B$10 -> 0 | G14: =(D14*F14/60)*Assumptions!$B$13 -> 0 | H14: =Assumptions!$B$5 -> 12 | I14: =G14*H14 -> 0 | J14: =I14*12 -> 0 | K14: Calendar management
A15: TOTAL | D15: =SUM(D5:D14) -> 303927 | G15: =SUM(G5:G14) -> 499046.67 | I15: =SUM(I5:I14) -> 5988560 | J15: =SUM(J5:J14) -> 71862720

Sheet Disruption Cost
A1: DISRUPTION COST ANALYSIS
A2: Quantifies the cost of service disruptions from billing failures and task overages
A4: KNOWN SERVICE DISRUPTIONS (2025)
A5: Outage Event | B5: Date | C5: Duration (days) | D5: Root Cause | E5: Tasks Not Processed | F5: Manual Workaround Cost | G5: Revenue at Risk | H5: Total Impact
A6: March 2025 - Task Overage | B6: 2025-03-26 | C6: 2 | D6: Hit 213% of 100k limit | E6: =C6*(Assumptions!$B$22/30) -> 1.6666667 | F6: =E6*8/60*Assumptions!$B$5 -> 2.6666667 | G6: =Assumptions!$B$16*Assumptions!$B$18*Assumptions!$B$19*(C6/Assumptions!$B$17) -> 0 | H6: =F6+G6 -> 2.6666667
A7: October 2025 - Billing Failure | B7: 2025-10-15 | C7: 7 | D7: Card payment failure, forced downgrade | E7: =C7*(Assumptions!$B$22/30) -> 5.8333333 | F7: =E7*8/60*Assumptions!$B$5 -> 9.3333333 | G7: =Assumptions!$B$16*Assumptions!$B$18*Assumptions!$B$19*(C7/Assumptions!$B$17) -> 0 | H7: =F7+G7 -> 9.3333333
A8: Q4 2025 - Zaps Never Reactivated | B8: 2025-10-22 | C8: 60 | D8: Zaps switched off, never turned back on | E8: =C8*(Assumptions!$B$22/30) -> 50 | F8: =E8*8/60*Assumptions!$B$5 -> 80 | G8: =Assumptions!$B$16*Assumptions!$B$18*Assumptions!$B$19*(C8/Assumptions!$B$17) -> 0 | H8: =F8+G8 -> 80
A9: TOTAL 2025 DISRUPTION COST | H9: =SUM(H6:H8) -> 92
A11: ONGOING DISRUPTION RISK (ANNUALIZED)
A12: Risk Category | B12: Probability/Year | C12: Avg Duration (days) | D12: Cost per Incident | E12: Expected Annual Cost | F12: Notes
A13: Task Overage (monthly billing) | B13: 0.25 | C13: 2 | D13: =(Assumptions!$B$22/30)*C13*8/60*Assumptions!$B$5 + C13*Assumptions!$B$21*Assumptions!$B$20 -> 17.666667 | E13: =B13*D13 -> 4.4166667 | F13: ~3 overages/year at current growth rate
A14: Payment/Billing Failure | B14: 0.15 | C14: 5 | D14: =(Assumptions!$B$22/30)*C14*8/60*Assumptions!$B$5 + C14*Assumptions!$B$21*Assumptions!$B$20 -> 44.166667 | E14: =B14*D14 -> 6.625 | F14: Card expiration, payment processing issues
A15: Platform Incident | B15: 0.1 | C15: 1 | D15: =(Assumptions!$B$22/30)*C15*8/60*Assumptions!$B$5 + C15*Assumptions!$B$21*Assumptions!$B$20 -> 8.8333333 | E15: =B15*D15 -> 0.88333333 | F15: Zapier platform-wide issues
A16: TOTAL ANNUAL DISRUPTION RISK | E16: =SUM(E13:E15) -> 11.925

Sheet Governance Risk
A1: GOVERNANCE & SECURITY RISK QUANTIFICATION
A2: Quantifies risk exposure from current ungoverned state vs. Enterprise controls
A4: CURRENT STATE RISK EXPOSURE
A5: Risk Category | B5: Current State | C5: Risk Metric | D5: Annual Probability | E5: Potential Cost | F5: Expected Annual Loss
A6: Data Breach (no SSO/SCIM) | B6: Any VA can connect any app to any data | D6: =Assumptions!$B$26 -> 150000 | E6: =Assumptions!$B$25 -> 0 | F6: =D6*E6 -> 0
A7: Shadow IT Proliferation | B7: 115 ungoverned free accounts | D7: 0.2 | E7: 50000 | F7: =D7*E7 -> 10000
A8: License Compliance | B8: 40+ users on 25-seat Teams cap | D8: 0.15 | E8: 25000 | F8: =D8*E8 -> 3750
A9: AI Data Leakage | B9: Teams ToS allows model training | D9: 0.05 | E9: 100000 | F9: =D9*E9 -> 5000
A10: Audit/Compliance Finding | B10: No audit trail, no RBAC | D10: 0.15 | E10: 25000 | F10: =D10*E10 -> 3750
A11: TOTAL CURRENT ANNUAL RISK EXPOSURE | F11: =SUM(F6:F10) -> 22500
A13: ENTERPRISE STATE - RISK REDUCTION
A14: Control | B14: Risk Mitigated | C14: Residual Probability | D14: Residual Cost | E14: Risk Reduction Value
A15: SSO/SAML | B15: Unauthorized access | C15: =Assumptions!$B$27 -> 0.08 | D15: =Assumptions!$B$25 -> 0 | E15: =F6-(C15*D15) -> 0
A16: SCIM Provisioning | B16: Shadow IT, orphaned accounts | C16: 0.05 | D16: 25000 | E16: =F7-(C16*D16) -> 8750
A17: RBAC/Workspace Governance | B17: Data exposure, compliance | C17: 0.05 | D17: 25000 | E17: =F8-(C17*D17) -> 2500
A18: Audit Logging | B18: Compliance findings | C18: 0.03 | D18: 10000 | E18: =F9-(C18*D18) -> 4700
A19: Enterprise ToS | B19: AI data concerns | C19: 0.01 | D19: 25000 | E19: =F10-(C19*D19) -> 3500
A20: TOTAL RISK REDUCTION VALUE | E20: =SUM(E15:E19) -> 19450

Sheet Executive Summary
A1: ATHENA - AUTOMATION ROI EXECUTIVE SUMMARY
A2: Total Value of Zapier Automation & Cost of Current State
A4: ANNUAL VALUE SUMMARY
A5: Category | B5: Annual Value | C5: Notes
A6: Automation Time Savings | B6: ='Zap-Level ROI'!J15 -> 71862720 | C6: Value of automated tasks vs. manual processing
A7: Disruption Cost Avoided (Historical) | B7: ='Disruption Cost'!H9 -> 92 | C7: Actual cost of 2025 outages
A8: Disruption Risk Reduction | B8: ='Disruption Cost'!E16 -> 11.925 | C8: Expected annual cost from ongoing risk
A9: Governance Risk Reduction | B9: ='Governance Risk'!E20 -> 19450 | C9: Security/compliance risk mitigation
A10: TOTAL ANNUAL VALUE / RISK REDUCTION | B10: =SUM(B6:B9) -> 71882274
A12: INVESTMENT COMPARISON
A13: Current State (Team 500K) | B13: 32388 | C13: ARR - monthly billing, no controls
A14: Proposed Enterprise Investment | B14: 54000 | C14: Enterprise 2.4M annual - adjust as needed
A15: Incremental Investment | B15: =B14-B13 -> 21612
A16: Net Annual Benefit | B16: =B10-B15 -> 71860662
A17: ROI Multiple | B17: =IF(B15>0,B10/B15,"-") -> 3326.0353 | C17: Total value divided by incremental investment
A19: KEY TALKING POINTS FOR ATHENA
A20: 1. Your top Zap alone (ELA processing) automates ~150k tasks/month - that's X hours of VA time saved
A21: 2. The October billing failure cost you $Y in manual workarounds + Z in delayed deals
A22: 3. With 115 ungoverned free accounts, you're carrying $X in annualized security risk
A23: 4. Enterprise eliminates the billing/overage disruption cycle that's hit you 3x in 2025
A24: 5. SSO/SCIM gives Esteban the controls he's been asking for since the original evaluation
